Workbook

Sheet Telangana Results 2024
A1: Year | B1: State Name | C1: PC Name | D1: Candidate Name | E1: Gender | F1: Age | G1: Category | H1: Party Name | I1: Party Symbol | J1: Total Votes Polled In The Constituency | K1: Valid Votes | L1: Votes Polled Per Party | M1: Party Vote Share Percentage | N1: Max Votes Other Than BJP | O1: Max Vote share other than bjp | P1: BJP votes | Q1: BJP vote share | R1: BJP Margin Votes | S1: BJP Margin Percentage | T1: Total Electors | U1: Voter Turnout | V1: BJP STATUS
A2: 2024 | B2: Telangana | C2: Adilabad | D2: GODAM NAGESH | E2: MALE | F2: 59 | G2: ST | H2: BJP | I2: Lotus | J2: 1238318 | K2: 1223835 | L2: 568168 | M2: 0.46425213 | N2: 477516 | O2: 0.39018005 | P2: 568168 | Q2: 0.46425213 | R2: =Telengana_Results_2024[[#This Row],[BJP votes]]-Telengana_Results_2024[[#This Row],[Max Votes Other Than BJP]] -> 90652 | S2: =Telengana_Results_2024[[#This Row],[BJP vote share]]-Telengana_Results_2024[[#This Row],[Max Vote share other than bjp ]] -> 0.074072077 | T2: 1652394 | U2: 0.74940843 | V2: BJP WON
A3: 2024 | B3: Telangana | C3: Adilabad | D3: ATHRAM SUGUNA | E3: FEMALE | F3: 49 | G3: ST | H3: INC | I3: Hand | J3: 1238318 | K3: 1223835 | L3: 477516 | M3: 0.39018005 | N3: 477516 | O3: 0.39018005 | P3: 568168 | Q3: 0.46425213 | R3: =Telengana_Results_2024[[#This Row],[BJP votes]]-Telengana_Results_2024[[#This Row],[Max Votes Other Than BJP]] -> 90652 | S3: =Telengana_Results_2024[[#This Row],[BJP vote share]]-Telengana_Results_2024[[#This Row],[Max Vote share other than bjp ]] -> 0.074072077 | T3: 1652394 | U3: 0.74940843 | V3: BJP WON
A4: 2024 | B4: Telangana | C4: Adilabad | D4: ATHRAM SAKKU | E4: MALE | F4: 51 | G4: ST | H4: BHRS | I4: Car | J4: 1238318 | K4: 1223835 | L4: 137300 | M4: 0.11218833 | N4: 477516 | O4: 0.39018005 | P4: 568168 | Q4: 0.46425213 | R4: =Telengana_Results_2024[[#This Row],[BJP votes]]-Telengana_Results_2024[[#This Row],[Max Votes Other Than BJP]] -> 90652 | S4: =Telengana_Results_2024[[#This Row],[BJP vote share]]-Telengana_Results_2024[[#This Row],[Max Vote share other than bjp ]] -> 0.074072077 | T4: 1652394 | U4: 0.74940843 | V4: BJP WON
A5: 2024 | B5: Telangana | C5: Adilabad | D5: NOTA | E5: NOTA | F5: NOTA | G5: NOTA | H5: NOTA | I5: NOTA | J5: 1238318 | K5: 1223835 | L5: 11762 | M5: 0.0096107727 | N5: 477516 | O5: 0.39018005 | P5: 568168 | Q5: 0.46425213 | R5: =Telengana_Results_2024[[#This Row],[BJP votes]]-Telengana_Results_2024[[#This Row],[Max Votes Other Than BJP]] -> 90652 | S5: =Telengana_Results_2024[[#This Row],[BJP vote share]]-Telengana_Results_2024[[#This Row],[Max Vote share other than bjp ]] -> 0.074072077 | T5: 1652394 | U5: 0.74940843 | V5: BJP WON
A6: 2024 | B6: Telangana | C6: Adilabad | D6: MALOTHU SYAMLAL NAYAK | E6: MALE | F6: 35 | G6: ST | H6: AODRP | I6: Chapati roller | J6: 1238318 | K6: 1223835 | L6: 7499 | M6: 0.00612746 | N6: 477516 | O6: 0.39018005 | P6: 568168 | Q6: 0.46425213 | R6: =Telengana_Results_2024[[#This Row],[BJP votes]]-Telengana_Results_2024[[#This Row],[Max Votes Other Than BJP]] -> 90652 | S6: =Telengana_Results_2024[[#This Row],[BJP vote share]]-Telengana_Results_2024[[#This Row],[Max Vote share other than bjp ]] -> 0.074072077 | T6: 1652394 | U6: 0.74940843 | V6: BJP WON
A7: 2024 | B7: Telangana | C7: Adilabad | D7: MESRAM JANGUBAPU | E7: MALE | F7: 34 | G7: ST | H7: BSP | I7: Elephant | J7: 1238318 | K7: 1223835 | L7: 6744 | M7: 0.0055105468 | N7: 477516 | O7: 0.39018005 | P7: 568168 | Q7: 0.46425213 | R7: =Telengana_Results_2024[[#This Row],[BJP votes]]-Telengana_Results_2024[[#This Row],[Max Votes Other Than BJP]] -> 90652 | S7: =Telengana_Results_2024[[#This Row],[BJP vote share]]-Telengana_Results_2024[[#This Row],[Max Vote share other than bjp ]] -> 0.074072077 | T7: 1652394 | U7: 0.74940843 | V7: BJP WON
A8: 2024 | B8: Telangana | C8: Adilabad | D8: RATHOD SUBASH | E8: MALE | F8: 40 | G8: ST | H8: IND | I8: Gas cylinder | J8: 1238318 | K8: 1223835 | L8: 6528 | M8: 0.0053340524 | N8: 477516 | O8: 0.39018005 | P8: 568168 | Q8: 0.46425213 | R8: =Telengana_Results_2024[[#This Row],[BJP votes]]-Telengana_Results_2024[[#This Row],[Max Votes Other Than BJP]] -> 90652 | S8: =Telengana_Results_2024[[#This Row],[BJP vote share]]-Telengana_Results_2024[[#This Row],[Max Vote share other than bjp ]] -> 0.074072077 | T8: 1652394 | U8: 0.74940843 | V8: BJP WON
A9: 2024 | B9: Telangana | C9: Adilabad | D9: BUKYA JAIVANTH RAO | E9: MALE | F9: 36 | G9: ST | H9: IND | I9: Pressure cooker | J9: 1238318 | K9: 1223835 | L9: 6446 | M9: 0.0052670499 | N9: 477516 | O9: 0.39018005 | P9: 568168 | Q9: 0.46425213 | R9: =Telengana_Results_2024[[#This Row],[BJP votes]]-Telengana_Results_2024[[#This Row],[Max Votes Other Than BJP]] -> 90652 | S9: =Telengana_Results_2024[[#This Row],[BJP vote share]]-Telengana_Results_2024[[#This Row],[Max Vote share other than bjp ]] -> 0.074072077 | T9: 1652394 | U9: 0.74940843 | V9: BJP WON
A10: 2024 | B10: Telangana | C10: Adilabad | D10: CHAVAN SUDHARSHAN | E10: MALE | F10: 45 | G10: ST | H10: AYSRCP | I10: Road roller | J10: 1238318 | K10: 1223835 | L10: 4644 | M10: 0.0037946292 | N10: 477516 | O10: 0.39018005 | P10: 568168 | Q10: 0.46425213 | R10: =Telengana_Results_2024[[#This Row],[BJP votes]]-Telengana_Results_2024[[#This Row],[Max Votes Other Than BJP]] -> 90652 | S10: =Telengana_Results_2024[[#This Row],[BJP vote share]]-Telengana_Results_2024[[#This Row],[Max Vote share other than bjp ]] -> 0.074072077 | T10: 1652394 | U10: 0.74940843 | V10: BJP WON
A11: 2024 | B11: Telangana | C11: Adilabad | D11: GANGADEVI MESRAM | E11: FEMALE | F11: 43 | G11: ST | H11: DHRMSMJP | I11: Chappals | J11: 1238318 | K11: 1223835 | L11: 3468 | M11: 0.0028337153 | N11: 477516 | O11: 0.39018005 | P11: 568168 | Q11: 0.46425213 | R11: =Telengana_Results_2024[[#This Row],[BJP votes]]-Telengana_Results_2024[[#This Row],[Max Votes Other Than BJP]] -> 90652 | S11: =Telengana_Results_2024[[#This Row],[BJP vote share]]-Telengana_Results_2024[[#This Row],[Max Vote share other than bjp ]] -> 0.074072077 | T11: 1652394 | U11: 0.74940843 | V11: BJP WON
A12: 2024 | B12: Telangana | C12: Adilabad | D12: N. TIRUPATI | E12: MALE | F12: 35 | G12: ST | H12: VTRP | I12: Bat | J12: 1238318 | K12: 1223835 | L12: 2292 | M12: 0.0018728015 | N12: 477516 | O12: 0.39018005 | P12: 568168 | Q12: 0.46425213 | R12: =Telengana_Results_2024[[#This Row],[BJP votes]]-Telengana_Results_2024[[#This Row],[Max Votes Other Than BJP]] -> 90652 | S12: =Telengana_Results_2024[[#This Row],[BJP vote share]]-Telengana_Results_2024[[#This Row],[Max Vote share other than bjp ]] -> 0.074072077 | T12: 1652394 | U12: 0.74940843 | V12: BJP WON
A13: 2024 | B13: Telangana | C13: Adilabad | D13: KODAPA VAMAN RAO | E13: MALE | F13: 40 | G13: ST | H13: GNDWDKP | I13: Man blowing turha | J13: 1238318 | K13: 1223835 | L13: 1685 | M13: 0.0013768196 | N13: 477516 | O13: 0.39018005 | P13: 568168 | Q13: 0.46425213 | R13: =Telengana_Results_2024[[#This Row],[BJP votes]]-Telengana_Results_2024[[#This Row],[Max Votes Other Than BJP]] -> 90652 | S13: =Telengana_Results_2024[[#This Row],[BJP vote share]]-Telengana_Results_2024[[#This Row],[Max Vote share other than bjp ]] -> 0.074072077 | T13: 1652394 | U13: 0.74940843 | V13: BJP WON
... A543: 2024 | B543: Telangana | C543: Khammam | D543: MUTYAM ARJUNA RAJU | E543: MALE | F543: 35 | G543: GENERAL | H543: IND | I543: T.V. Remote | J543: 1252286 | K543: 1244501 | L543: 351 | M543: 0.00028204075 | N543: 766929 | O543: 0.61625423 | P543: 118636 | Q543: 0.095328168 | R543: =Telengana_Results_2024[[#This Row],[BJP votes]]-Telengana_Results_2024[[#This Row],[Max Votes Other Than BJP]] -> -648293 | S543: =Telengana_Results_2024[[#This Row],[BJP vote share]]-Telengana_Results_2024[[#This Row],[Max Vote share other than bjp ]] -> -0.52092606 | T543: 1631952 | U543: 0.76735468 | V543: BJP LOST
R544: =Telengana_Results_2024[[#This Row],[BJP votes]]-Telengana_Results_2024[[#This Row],[Max Votes Other Than BJP]] -> 0 | S544: =Telengana_Results_2024[[#This Row],[BJP vote share]]-Telengana_Results_2024[[#This Row],[Max Vote share other than bjp ]] -> 0

Sheet Telangana Results 2019
A1: Year | B1: State Name | C1: PC Name | D1: CANDIDATES NAME | E1: SEX | F1: AGE | G1: CATEGORY | H1: PARTY NAME | I1: PARTY SYMBOL | J1: Votes Polled Per Party | K1: Party Vote Share | L1: Max Votes Share other than BJP | M1: Max Votes Other than BJP | N1: BJP Votes | O1: BJP Vote Share | P1: BJP Vote Margin | Q1: BJP Margin Percentage | R1: Total Votes Polled | S1: Total Electors | T1: Voter Turnout | U1: BJP_STATUS
A2: 2019 | B2: Telangana | C2: Adilabad | D2: Godam Nagesh | E2: MALE | F2: 54 | G2: ST | H2: TRS | I2: Car | J2: 318814 | K2: 0.29971327 | L2: 0.29971327 | M2: 318814 | N2: 377374 | O2: 0.35476484 | P2: =Telengana_Reaults_2019[[#This Row],[BJP Votes]]-Telengana_Reaults_2019[[#This Row],[Max Votes Other than BJP]] -> 58560 | Q2: =Telengana_Reaults_2019[[#This Row],[BJP Vote Share]]-Telengana_Reaults_2019[[#This Row],[Max Votes Share other than BJP]] -> 0.055051564 | R2: 1063730 | S2: 1489790 | T2: 0.71401338 | U2: BJP WON
A3: 2019 | B3: Telangana | C3: Adilabad | D3: RATHOD RAMESH | E3: MALE | F3: 52 | G3: ST | H3: INC | I3: Hand | J3: 314238 | K3: 0.29541143 | L3: 0.29971327 | M3: 318814 | N3: 377374 | O3: 0.35476484 | P3: =Telengana_Reaults_2019[[#This Row],[BJP Votes]]-Telengana_Reaults_2019[[#This Row],[Max Votes Other than BJP]] -> 58560 | Q3: =Telengana_Reaults_2019[[#This Row],[BJP Vote Share]]-Telengana_Reaults_2019[[#This Row],[Max Votes Share other than BJP]] -> 0.055051564 | R3: 1063730 | S3: 1489790 | T3: 0.71401338 | U3: BJP WON
A4: 2019 | B4: Telangana | C4: Adilabad | D4: SOYAM BAPU RAO | E4: MALE | F4: 52 | G4: ST | H4: BJP | I4: Lotus | J4: 377374 | K4: 0.35476484 | L4: 0.29971327 | M4: 318814 | N4: 377374 | O4: 0.35476484 | P4: =Telengana_Reaults_2019[[#This Row],[BJP Votes]]-Telengana_Reaults_2019[[#This Row],[Max Votes Other than BJP]] -> 58560 | Q4: =Telengana_Reaults_2019[[#This Row],[BJP Vote Share]]-Telengana_Reaults_2019[[#This Row],[Max Votes Share other than BJP]] -> 0.055051564 | R4: 1063730 | S4: 1489790 | T4: 0.71401338 | U4: BJP WON
A5: 2019 | B5: Telangana | C5: Adilabad | D5: KUMRAM VANDANA | E5: FEMALE | F5: 35 | G5: ST | H5: NPRP | I5: Tractor Chalata Kisan | J5: 8007 | K5: 0.0075272861 | L5: 0.29971327 | M5: 318814 | N5: 377374 | O5: 0.35476484 | P5: =Telengana_Reaults_2019[[#This Row],[BJP Votes]]-Telengana_Reaults_2019[[#This Row],[Max Votes Other than BJP]] -> 58560 | Q5: =Telengana_Reaults_2019[[#This Row],[BJP Vote Share]]-Telengana_Reaults_2019[[#This Row],[Max Votes Share other than BJP]] -> 0.055051564 | R5: 1063730 | S5: 1489790 | T5: 0.71401338 | U5: BJP WON
A6: 2019 | B6: Telangana | C6: Adilabad | D6: Dharavath Narendhar Naik | E6: MALE | F6: 27 | G6: ST | H6: JnP | I6: Glass Tumbler | J6: 5241 | K6: 0.0049270022 | L6: 0.29971327 | M6: 318814 | N6: 377374 | O6: 0.35476484 | P6: =Telengana_Reaults_2019[[#This Row],[BJP Votes]]-Telengana_Reaults_2019[[#This Row],[Max Votes Other than BJP]] -> 58560 | Q6: =Telengana_Reaults_2019[[#This Row],[BJP Vote Share]]-Telengana_Reaults_2019[[#This Row],[Max Votes Share other than BJP]] -> 0.055051564 | R6: 1063730 | S6: 1489790 | T6: 0.71401338 | U6: BJP WON
A7: 2019 | B7: Telangana | C7: Adilabad | D7: Pawar Krishna | E7: MALE | F7: 38 | G7: ST | H7: RaJPa | I7: Helmet | J7: 2705 | K7: 0.0025429385 | L7: 0.29971327 | M7: 318814 | N7: 377374 | O7: 0.35476484 | P7: =Telengana_Reaults_2019[[#This Row],[BJP Votes]]-Telengana_Reaults_2019[[#This Row],[Max Votes Other than BJP]] -> 58560 | Q7: =Telengana_Reaults_2019[[#This Row],[BJP Vote Share]]-Telengana_Reaults_2019[[#This Row],[Max Votes Share other than BJP]] -> 0.055051564 | R7: 1063730 | S7: 1489790 | T7: 0.71401338 | U7: BJP WON
A8: 2019 | B8: Telangana | C8: Adilabad | D8: Bheemrao | E8: MALE | F8: 33 | G8: ST | H8: APoI | I8: Coat | J8: 6837 | K8: 0.0064273829 | L8: 0.29971327 | M8: 318814 | N8: 377374 | O8: 0.35476484 | P8: =Telengana_Reaults_2019[[#This Row],[BJP Votes]]-Telengana_Reaults_2019[[#This Row],[Max Votes Other than BJP]] -> 58560 | Q8: =Telengana_Reaults_2019[[#This Row],[BJP Vote Share]]-Telengana_Reaults_2019[[#This Row],[Max Votes Share other than BJP]] -> 0.055051564 | R8: 1063730 | S8: 1489790 | T8: 0.71401338 | U8: BJP WON
A9: 2019 | B9: Telangana | C9: Adilabad | D9: Aare Ellanna | E9: MALE | F9: 53 | G9: ST | H9: IND | I9: Bat | J9: 3019 | K9: 0.0028381262 | L9: 0.29971327 | M9: 318814 | N9: 377374 | O9: 0.35476484 | P9: =Telengana_Reaults_2019[[#This Row],[BJP Votes]]-Telengana_Reaults_2019[[#This Row],[Max Votes Other than BJP]] -> 58560 | Q9: =Telengana_Reaults_2019[[#This Row],[BJP Vote Share]]-Telengana_Reaults_2019[[#This Row],[Max Votes Share other than BJP]] -> 0.055051564 | R9: 1063730 | S9: 1489790 | T9: 0.71401338 | U9: BJP WON
A10: 2019 | B10: Telangana | C10: Adilabad | D10: Kumra Raju | E10: MALE | F10: 29 | G10: ST | H10: IND | I10: Ring | J10: 4388 | K10: 0.0041251069 | L10: 0.29971327 | M10: 318814 | N10: 377374 | O10: 0.35476484 | P10: =Telengana_Reaults_2019[[#This Row],[BJP Votes]]-Telengana_Reaults_2019[[#This Row],[Max Votes Other than BJP]] -> 58560 | Q10: =Telengana_Reaults_2019[[#This Row],[BJP Vote Share]]-Telengana_Reaults_2019[[#This Row],[Max Votes Share other than BJP]] -> 0.055051564 | R10: 1063730 | S10: 1489790 | T10: 0.71401338 | U10: BJP WON
A11: 2019 | B11: Telangana | C11: Adilabad | D11: Ganta Pentanna | E11: MALE | F11: 47 | G11: ST | H11: IND | I11: Pot | J11: 4548 | K11: 0.004275521 | L11: 0.29971327 | M11: 318814 | N11: 377374 | O11: 0.35476484 | P11: =Telengana_Reaults_2019[[#This Row],[BJP Votes]]-Telengana_Reaults_2019[[#This Row],[Max Votes Other than BJP]] -> 58560 | Q11: =Telengana_Reaults_2019[[#This Row],[BJP Vote Share]]-Telengana_Reaults_2019[[#This Row],[Max Votes Share other than BJP]] -> 0.055051564 | R11: 1063730 | S11: 1489790 | T11: 0.71401338 | U11: BJP WON
A12: 2019 | B12: Telangana | C12: Adilabad | D12: Nethavath Ramdas | E12: MALE | F12: 46 | G12: ST | H12: IND | I12: Gas Cylinder | J12: 5523 | K12: 0.005192107 | L12: 0.29971327 | M12: 318814 | N12: 377374 | O12: 0.35476484 | P12: =Telengana_Reaults_2019[[#This Row],[BJP Votes]]-Telengana_Reaults_2019[[#This Row],[Max Votes Other than BJP]] -> 58560 | Q12: =Telengana_Reaults_2019[[#This Row],[BJP Vote Share]]-Telengana_Reaults_2019[[#This Row],[Max Votes Share other than BJP]] -> 0.055051564 | R12: 1063730 | S12: 1489790 | T12: 0.71401338 | U12: BJP WON
A13: 2019 | B13: Telangana | C13: Adilabad | D13: NOTA | E13: NOTA | F13: NOTA | G13: NOTA | H13: NOTA | I13: NOTA | J13: 13036 | K13: 0.01225499 | L13: 0.29971327 | M13: 318814 | N13: 377374 | O13: 0.35476484 | P13: =Telengana_Reaults_2019[[#This Row],[BJP Votes]]-Telengana_Reaults_2019[[#This Row],[Max Votes Other than BJP]] -> 58560 | Q13: =Telengana_Reaults_2019[[#This Row],[BJP Vote Share]]-Telengana_Reaults_2019[[#This Row],[Max Votes Share other than BJP]] -> 0.055051564 | R13: 1063730 | S13: 1489790 | T13: 0.71401338 | U13: BJP WON
... A461: 2019 | B461: Telangana | C461: Khammam | D461: NOTA | E461: NOTA | F461: NOTA | G461: NOTA | H461: NOTA | I461: NOTA | J461: 15832 | K461: 0.013889778 | L461: 0.49784486 | M461: 567459 | N461: 20488 | O461: 0.017974594 | P461: =Telengana_Reaults_2019[[#This Row],[BJP Votes]]-Telengana_Reaults_2019[[#This Row],[Max Votes Other than BJP]] -> -546971 | Q461: =Telengana_Reaults_2019[[#This Row],[BJP Vote Share]]-Telengana_Reaults_2019[[#This Row],[Max Votes Share other than BJP]] -> -0.47987026 | R461: 1139831 | S461: 1513809 | T461: 0.75295562 | U461: BJP LOST

Sheet BJP Seat Grading
A1: Sr.No | B1: PC Name | C1: BJP Margin Votes 2019 | D1: BJP Margin Percentage 2019 | E1: BJP Margin Votes 2024 | F1: BJP Margin Percentage 2024 | G1: Average Margin Votes | H1: Average Margin Percentage | I1: Seat Grade
A2: 1 | B2: Adilabad | C2: =VLOOKUP(B2,Telengana_Reaults_2019[[#All],[PC Name]:[BJP_STATUS]],14,FALSE) -> 58560 | D2: =VLOOKUP(B2,Telengana_Reaults_2019[[#All],[PC Name]:[BJP_STATUS]],15,FALSE) -> 0.055051564 | E2: =VLOOKUP(Table3[[#This Row],[PC Name]],Telengana_Results_2024[[PC Name]:[BJP STATUS]],16,FALSE) -> 90652 | F2: =VLOOKUP(Table3[[#This Row],[PC Name]],Telengana_Results_2024[[PC Name]:[BJP STATUS]],17,FALSE) -> 0.074072077 | G2: =(Table3[[#This Row],[BJP Margin Votes 2024]]+Table3[[#This Row],[BJP Margin Votes 2019]])/2 -> 74606 | H2: =(Table3[[#This Row],[BJP Margin Percentage 2024]]+Table3[[#This Row],[BJP Margin Percentage 2019]])/2 -> 0.06456182 | I2: =_xlfn.IFS(H2>=0.1,"Strong Hold", H2>=0.05,"Average Hold", H2>=-0.05,"Weak Hold", TRUE, "Very Vulnerable Hold") -> Average Hold
A3: 2 | B3: Peddapalle | C3: =VLOOKUP(B3,Telengana_Reaults_2019[[#All],[PC Name]:[BJP_STATUS]],14,FALSE) -> -348715 | D3: =VLOOKUP(B3,Telengana_Reaults_2019[[#All],[PC Name]:[BJP_STATUS]],15,FALSE) -> -0.3594811 | E3: =VLOOKUP(Table3[[#This Row],[PC Name]],Telengana_Results_2024[[PC Name]:[BJP STATUS]],16,FALSE) -> -131364 | F3: =VLOOKUP(Table3[[#This Row],[PC Name]],Telengana_Results_2024[[PC Name]:[BJP STATUS]],17,FALSE) -> -0.12056344 | G3: =(Table3[[#This Row],[BJP Margin Votes 2024]]+Table3[[#This Row],[BJP Margin Votes 2019]])/2 -> -240039.5 | H3: =(Table3[[#This Row],[BJP Margin Percentage 2024]]+Table3[[#This Row],[BJP Margin Percentage 2019]])/2 -> -0.24002227 | I3: =_xlfn.IFS(H3>=0.1,"Strong Hold", H3>=0.05,"Average Hold", H3>=-0.05,"Weak Hold", TRUE, "Very Vulnerable Hold") -> Very Vulnerable Hold
A4: 3 | B4: Karimnagar | C4: =VLOOKUP(B4,Telengana_Reaults_2019[[#All],[PC Name]:[BJP_STATUS]],14,FALSE) -> 89508 | D4: =VLOOKUP(B4,Telengana_Reaults_2019[[#All],[PC Name]:[BJP_STATUS]],15,FALSE) -> 0.077989225 | E4: =VLOOKUP(Table3[[#This Row],[PC Name]],Telengana_Results_2024[[PC Name]:[BJP STATUS]],16,FALSE) -> 225209 | F4: =VLOOKUP(Table3[[#This Row],[PC Name]],Telengana_Results_2024[[PC Name]:[BJP STATUS]],17,FALSE) -> 0.17225531 | G4: =(Table3[[#This Row],[BJP Margin Votes 2024]]+Table3[[#This Row],[BJP Margin Votes 2019]])/2 -> 157358.5 | H4: =(Table3[[#This Row],[BJP Margin Percentage 2024]]+Table3[[#This Row],[BJP Margin Percentage 2019]])/2 -> 0.12512227 | I4: =_xlfn.IFS(H4>=0.1,"Strong Hold", H4>=0.05,"Average Hold", H4>=-0.05,"Weak Hold", TRUE, "Very Vulnerable Hold") -> Strong Hold
A5: 4 | B5: Nizamabad | C5: =VLOOKUP(B5,Telengana_Reaults_2019[[#All],[PC Name]:[BJP_STATUS]],14,FALSE) -> 70875 | D5: =VLOOKUP(B5,Telengana_Reaults_2019[[#All],[PC Name]:[BJP_STATUS]],15,FALSE) -> 0.066689061 | E5: =VLOOKUP(Table3[[#This Row],[PC Name]],Telengana_Results_2024[[PC Name]:[BJP STATUS]],16,FALSE) -> 109241 | F5: =VLOOKUP(Table3[[#This Row],[PC Name]],Telengana_Results_2024[[PC Name]:[BJP STATUS]],17,FALSE) -> 0.088878999 | G5: =(Table3[[#This Row],[BJP Margin Votes 2024]]+Table3[[#This Row],[BJP Margin Votes 2019]])/2 -> 90058 | H5: =(Table3[[#This Row],[BJP Margin Percentage 2024]]+Table3[[#This Row],[BJP Margin Percentage 2019]])/2 -> 0.07778403 | I5: =_xlfn.IFS(H5>=0.1,"Strong Hold", H5>=0.05,"Average Hold", H5>=-0.05,"Weak Hold", TRUE, "Very Vulnerable Hold") -> Average Hold
A6: 5 | B6: Zahirabad | C6: =VLOOKUP(B6,Telengana_Reaults_2019[[#All],[PC Name]:[BJP_STATUS]],14,FALSE) -> -295297 | D6: =VLOOKUP(B6,Telengana_Reaults_2019[[#All],[PC Name]:[BJP_STATUS]],15,FALSE) -> -0.28275268 | E6: =VLOOKUP(Table3[[#This Row],[PC Name]],Telengana_Results_2024[[PC Name]:[BJP STATUS]],16,FALSE) -> -46188 | F6: =VLOOKUP(Table3[[#This Row],[PC Name]],Telengana_Results_2024[[PC Name]:[BJP STATUS]],17,FALSE) -> -0.037441149 | G6: =(Table3[[#This Row],[BJP Margin Votes 2024]]+Table3[[#This Row],[BJP Margin Votes 2019]])/2 -> -170742.5 | H6: =(Table3[[#This Row],[BJP Margin Percentage 2024]]+Table3[[#This Row],[BJP Margin Percentage 2019]])/2 -> -0.16009691 | I6: =_xlfn.IFS(H6>=0.1,"Strong Hold", H6>=0.05,"Average Hold", H6>=-0.05,"Weak Hold", TRUE, "Very Vulnerable Hold") -> Very Vulnerable Hold
A7: 6 | B7: Medak | C7: =VLOOKUP(B7,Telengana_Reaults_2019[[#All],[PC Name]:[BJP_STATUS]],14,FALSE) -> -394481 | D7: =VLOOKUP(B7,Telengana_Reaults_2019[[#All],[PC Name]:[BJP_STATUS]],15,FALSE) -> -0.34296045 | E7: =VLOOKUP(Table3[[#This Row],[PC Name]],Telengana_Results_2024[[PC Name]:[BJP STATUS]],16,FALSE) -> 39139 | F7: =VLOOKUP(Table3[[#This Row],[PC Name]],Telengana_Results_2024[[PC Name]:[BJP STATUS]],17,FALSE) -> 0.028328298 | G7: =(Table3[[#This Row],[BJP Margin Votes 2024]]+Table3[[#This Row],[BJP Margin Votes 2019]])/2 -> -177671 | H7: =(Table3[[#This Row],[BJP Margin Percentage 2024]]+Table3[[#This Row],[BJP Margin Percentage 2019]])/2 -> -0.15731608 | I7: =_xlfn.IFS(H7>=0.1,"Strong Hold", H7>=0.05,"Average Hold", H7>=-0.05,"Weak Hold", TRUE, "Very Vulnerable Hold") -> Very Vulnerable Hold
A8: 7 | B8: Malkajgiri | C8: =VLOOKUP(B8,Telengana_Reaults_2019[[#All],[PC Name]:[BJP_STATUS]],14,FALSE) -> -299466 | D8: =VLOOKUP(B8,Telengana_Reaults_2019[[#All],[PC Name]:[BJP_STATUS]],15,FALSE) -> -0.19158921 | E8: =VLOOKUP(Table3[[#This Row],[PC Name]],Telengana_Results_2024[[PC Name]:[BJP STATUS]],16,FALSE) -> 391475 | F8: =VLOOKUP(Table3[[#This Row],[PC Name]],Telengana_Results_2024[[PC Name]:[BJP STATUS]],17,FALSE) -> 0.20384259 | G8: =(Table3[[#This Row],[BJP Margin Votes 2024]]+Table3[[#This Row],[BJP Margin Votes 2019]])/2 -> 46004.5 | H8: =(Table3[[#This Row],[BJP Margin Percentage 2024]]+Table3[[#This Row],[BJP Margin Percentage 2019]])/2 -> 0.0061266902 | I8: =_xlfn.IFS(H8>=0.1,"Strong Hold", H8>=0.05,"Average Hold", H8>=-0.05,"Weak Hold", TRUE, "Very Vulnerable Hold") -> Weak Hold
A9: 8 | B9: Secundrabad | C9: =VLOOKUP(B9,Telengana_Reaults_2019[[#All],[PC Name]:[BJP_STATUS]],14,FALSE) -> 62114 | D9: =VLOOKUP(B9,Telengana_Reaults_2019[[#All],[PC Name]:[BJP_STATUS]],15,FALSE) -> 0.06787629 | E9: =VLOOKUP(Table3[[#This Row],[PC Name]],Telengana_Results_2024[[PC Name]:[BJP STATUS]],16,FALSE) -> 49944 | F9: =VLOOKUP(Table3[[#This Row],[PC Name]],Telengana_Results_2024[[PC Name]:[BJP STATUS]],17,FALSE) -> 0.047908235 | G9: =(Table3[[#This Row],[BJP Margin Votes 2024]]+Table3[[#This Row],[BJP Margin Votes 2019]])/2 -> 56029 | H9: =(Table3[[#This Row],[BJP Margin Percentage 2024]]+Table3[[#This Row],[BJP Margin Percentage 2019]])/2 -> 0.057892263 | I9: =_xlfn.IFS(H9>=0.1,"Strong Hold", H9>=0.05,"Average Hold", H9>=-0.05,"Weak Hold", TRUE, "Very Vulnerable Hold") -> Average Hold
A10: 9 | B10: Hyderabad | C10: =VLOOKUP(B10,Telengana_Reaults_2019[[#All],[PC Name]:[BJP_STATUS]],14,FALSE) -> -282186 | D10: =VLOOKUP(B10,Telengana_Reaults_2019[[#All],[PC Name]:[BJP_STATUS]],15,FALSE) -> -0.32144322 | E10: =VLOOKUP(Table3[[#This Row],[PC Name]],Telengana_Results_2024[[PC Name]:[BJP STATUS]],16,FALSE) -> -338087 | F10: =VLOOKUP(Table3[[#This Row],[PC Name]],Telengana_Results_2024[[PC Name]:[BJP STATUS]],17,FALSE) -> -0.31379372 | G10: =(Table3[[#This Row],[BJP Margin Votes 2024]]+Table3[[#This Row],[BJP Margin Votes 2019]])/2 -> -310136.5 | H10: =(Table3[[#This Row],[BJP Margin Percentage 2024]]+Table3[[#This Row],[BJP Margin Percentage 2019]])/2 -> -0.31761847 | I10: =_xlfn.IFS(H10>=0.1,"Strong Hold", H10>=0.05,"Average Hold", H10>=-0.05,"Weak Hold", TRUE, "Very Vulnerable Hold") -> Very Vulnerable Hold
A11: 10 | B11: Chevella | C11: =VLOOKUP(B11,Telengana_Reaults_2019[[#All],[PC Name]:[BJP_STATUS]],14,FALSE) -> -326188 | D11: =VLOOKUP(B11,Telengana_Reaults_2019[[#All],[PC Name]:[BJP_STATUS]],15,FALSE) -> -0.25087641 | E11: =VLOOKUP(Table3[[#This Row],[PC Name]],Telengana_Results_2024[[PC Name]:[BJP STATUS]],16,FALSE) -> 172897 | F11: =VLOOKUP(Table3[[#This Row],[PC Name]],Telengana_Results_2024[[PC Name]:[BJP STATUS]],17,FALSE) -> 0.10359745 | G11: =(Table3[[#This Row],[BJP Margin Votes 2024]]+Table3[[#This Row],[BJP Margin Votes 2019]])/2 -> -76645.5 | H11: =(Table3[[#This Row],[BJP Margin Percentage 2024]]+Table3[[#This Row],[BJP Margin Percentage 2019]])/2 -> -0.073639478 | I11: =_xlfn.IFS(H11>=0.1,"Strong Hold", H11>=0.05,"Average Hold", H11>=-0.05,"Weak Hold", TRUE, "Very Vulnerable Hold") -> Very Vulnerable Hold
A12: 11 | B12: Mahbubnagar | C12: =VLOOKUP(B12,Telengana_Reaults_2019[[#All],[PC Name]:[BJP_STATUS]],14,FALSE) -> -77829 | D12: =VLOOKUP(B12,Telengana_Reaults_2019[[#All],[PC Name]:[BJP_STATUS]],15,FALSE) -> -0.079043584 | E12: =VLOOKUP(Table3[[#This Row],[PC Name]],Telengana_Results_2024[[PC Name]:[BJP STATUS]],16,FALSE) -> 4500 | F12: =VLOOKUP(Table3[[#This Row],[PC Name]],Telengana_Results_2024[[PC Name]:[BJP STATUS]],17,FALSE) -> 0.0036832473 | G12: =(Table3[[#This Row],[BJP Margin Votes 2024]]+Table3[[#This Row],[BJP Margin Votes 2019]])/2 -> -36664.5 | H12: =(Table3[[#This Row],[BJP Margin Percentage 2024]]+Table3[[#This Row],[BJP Margin Percentage 2019]])/2 -> -0.037680168 | I12: =_xlfn.IFS(H12>=0.1,"Strong Hold", H12>=0.05,"Average Hold", H12>=-0.05,"Weak Hold", TRUE, "Very Vulnerable Hold") -> Weak Hold
A13: 12 | B13: Nagarkurnool | C13: =VLOOKUP(B13,Telengana_Reaults_2019[[#All],[PC Name]:[BJP_STATUS]],14,FALSE) -> -370651 | D13: =VLOOKUP(B13,Telengana_Reaults_2019[[#All],[PC Name]:[BJP_STATUS]],15,FALSE) -> -0.37445282 | E13: =VLOOKUP(Table3[[#This Row],[PC Name]],Telengana_Results_2024[[PC Name]:[BJP STATUS]],16,FALSE) -> -94414 | F13: =VLOOKUP(Table3[[#This Row],[PC Name]],Telengana_Results_2024[[PC Name]:[BJP STATUS]],17,FALSE) -> -0.077729835 | G13: =(Table3[[#This Row],[BJP Margin Votes 2024]]+Table3[[#This Row],[BJP Margin Votes 2019]])/2 -> -232532.5 | H13: =(Table3[[#This Row],[BJP Margin Percentage 2024]]+Table3[[#This Row],[BJP Margin Percentage 2019]])/2 -> -0.22609133 | I13: =_xlfn.IFS(H13>=0.1,"Strong Hold", H13>=0.05,"Average Hold", H13>=-0.05,"Weak Hold", TRUE, "Very Vulnerable Hold") -> Very Vulnerable Hold
... A18: 17 | B18: Khammam | C18: =VLOOKUP(B18,Telengana_Reaults_2019[[#All],[PC Name]:[BJP_STATUS]],14,FALSE) -> -546971 | D18: =VLOOKUP(B18,Telengana_Reaults_2019[[#All],[PC Name]:[BJP_STATUS]],15,FALSE) -> -0.47987026 | E18: =VLOOKUP(Table3[[#This Row],[PC Name]],Telengana_Results_2024[[PC Name]:[BJP STATUS]],16,FALSE) -> -648293 | F18: =VLOOKUP(Table3[[#This Row],[PC Name]],Telengana_Results_2024[[PC Name]:[BJP STATUS]],17,FALSE) -> -0.52092606 | G18: =(Table3[[#This Row],[BJP Margin Votes 2024]]+Table3[[#This Row],[BJP Margin Votes 2019]])/2 -> -597632 | H18: =(Table3[[#This Row],[BJP Margin Percentage 2024]]+Table3[[#This Row],[BJP Margin Percentage 2019]])/2 -> -0.50039816 | I18: =_xlfn.IFS(H18>=0.1,"Strong Hold", H18>=0.05,"Average Hold", H18>=-0.05,"Weak Hold", TRUE, "Very Vulnerable Hold") -> Very Vulnerable Hold

Sheet Voter TurnOut Analysis 
A1: Sr.No | B1: PC Name | C1: BJP Share 2019 | D1: Voter TurnOut 2019 | E1: BJP Share 2024 | F1: Voter TurnOut 2024 | G1: BJP vote share Swing | H1: Turn out swing | I1: Ratio | J1: Conversion Rate
A2: 1 | B2: Adilabad | C2: =VLOOKUP(B2,Telengana_Reaults_2019[[#All],[PC Name]:[BJP_STATUS]],13,FALSE) -> 0.35476484 | D2: =VLOOKUP(B2,Telengana_Reaults_2019[[#All],[PC Name]:[BJP_STATUS]], 18,FALSE) -> 0.71401338 | E2: =VLOOKUP(B2,Telengana_Results_2024[[#All],[PC Name]:[BJP vote share]],15,FALSE) -> 0.46425213 | F2: =VLOOKUP(B2,Telengana_Results_2024[[#All],[PC Name]:[BJP STATUS]],19,FALSE) -> 0.74940843 | G2: =E2-C2 -> 0.10948729 | H2: =F2-D2 -> 0.03539505 | I2: =G2/H2 -> 3.0932938 | J2: =_xlfn.IFS(I2>5,"High Conversion- Mobilize Voters", I2>=3,"Moderate Conversion- Make the existing Base Stronger", TRUE,"Low Conversion- Can be ignored") -> Moderate Conversion- Make the existing Base Stronger
A3: 2 | B3: Peddapalle | C3: =VLOOKUP(B3,Telengana_Reaults_2019[[#All],[PC Name]:[BJP_STATUS]],13,FALSE) -> 0.095465084 | D3: =VLOOKUP(B3,Telengana_Reaults_2019[[#All],[PC Name]:[BJP_STATUS]], 18,FALSE) -> 0.65584268 | E3: =VLOOKUP(B3,Telengana_Results_2024[[#All],[PC Name]:[BJP vote share]],15,FALSE) -> 0.31592149 | F3: =VLOOKUP(B3,Telengana_Results_2024[[#All],[PC Name]:[BJP STATUS]],19,FALSE) -> 0.68632423 | G3: =E3-C3 -> 0.22045641 | H3: =F3-D3 -> 0.030481556 | I3: =G3/H3 -> 7.2324525 | J3: =_xlfn.IFS(I3>5,"High Conversion- Mobilize Voters", I3>=3,"Moderate Conversion- Make the existing Base Stronger", TRUE,"Low Conversion- Can be ignored") -> High Conversion- Mobilize Voters
A4: 3 | B4: Karimnagar | C4: =VLOOKUP(B4,Telengana_Reaults_2019[[#All],[PC Name]:[BJP_STATUS]],13,FALSE) -> 0.43415292 | D4: =VLOOKUP(B4,Telengana_Reaults_2019[[#All],[PC Name]:[BJP_STATUS]], 18,FALSE) -> 0.69492408 | E4: =VLOOKUP(B4,Telengana_Results_2024[[#All],[PC Name]:[BJP vote share]],15,FALSE) -> 0.44753689 | F4: =VLOOKUP(B4,Telengana_Results_2024[[#All],[PC Name]:[BJP STATUS]],19,FALSE) -> 0.73106295 | G4: =E4-C4 -> 0.013383977 | H4: =F4-D4 -> 0.036138868 | I4: =G4/H4 -> 0.37034853 | J4: =_xlfn.IFS(I4>5,"High Conversion- Mobilize Voters", I4>=3,"Moderate Conversion- Make the existing Base Stronger", TRUE,"Low Conversion- Can be ignored") -> Low Conversion- Can be ignored
A5: 4 | B5: Nizamabad | C5: =VLOOKUP(B5,Telengana_Reaults_2019[[#All],[PC Name]:[BJP_STATUS]],13,FALSE) -> 0.45220029 | D5: =VLOOKUP(B5,Telengana_Reaults_2019[[#All],[PC Name]:[BJP_STATUS]], 18,FALSE) -> 0.68416265 | E5: =VLOOKUP(B5,Telengana_Results_2024[[#All],[PC Name]:[BJP vote share]],15,FALSE) -> 0.48191275 | F5: =VLOOKUP(B5,Telengana_Results_2024[[#All],[PC Name]:[BJP STATUS]],19,FALSE) -> 0.72349995 | G5: =E5-C5 -> 0.02971246 | H5: =F5-D5 -> 0.039337297 | I5: =G5/H5 -> 0.75532542 | J5: =_xlfn.IFS(I5>5,"High Conversion- Mobilize Voters", I5>=3,"Moderate Conversion- Make the existing Base Stronger", TRUE,"Low Conversion- Can be ignored") -> Low Conversion- Can be ignored
A6: 5 | B6: Zahirabad | C6: =VLOOKUP(B6,Telengana_Reaults_2019[[#All],[PC Name]:[BJP_STATUS]],13,FALSE) -> 0.13304448 | D6: =VLOOKUP(B6,Telengana_Reaults_2019[[#All],[PC Name]:[BJP_STATUS]], 18,FALSE) -> 0.69686308 | E6: =VLOOKUP(B6,Telengana_Results_2024[[#All],[PC Name]:[BJP vote share]],15,FALSE) -> 0.39090771 | F6: =VLOOKUP(B6,Telengana_Results_2024[[#All],[PC Name]:[BJP STATUS]],19,FALSE) -> 0.75295797 | G6: =E6-C6 -> 0.25786322 | H6: =F6-D6 -> 0.056094897 | I6: =G6/H6 -> 4.5969106 | J6: =_xlfn.IFS(I6>5,"High Conversion- Mobilize Voters", I6>=3,"Moderate Conversion- Make the existing Base Stronger", TRUE,"Low Conversion- Can be ignored") -> Moderate Conversion- Make the existing Base Stronger
A7: 6 | B7: Medak | C7: =VLOOKUP(B7,Telengana_Reaults_2019[[#All],[PC Name]:[BJP_STATUS]],13,FALSE) -> 0.17524167 | D7: =VLOOKUP(B7,Telengana_Reaults_2019[[#All],[PC Name]:[BJP_STATUS]], 18,FALSE) -> 0.71740166 | E7: =VLOOKUP(B7,Telengana_Results_2024[[#All],[PC Name]:[BJP vote share]],15,FALSE) -> 0.34106072 | F7: =VLOOKUP(B7,Telengana_Results_2024[[#All],[PC Name]:[BJP STATUS]],19,FALSE) -> 0.75857063 | G7: =E7-C7 -> 0.16581905 | H7: =F7-D7 -> 0.041168963 | I7: =G7/H7 -> 4.0277685 | J7: =_xlfn.IFS(I7>5,"High Conversion- Mobilize Voters", I7>=3,"Moderate Conversion- Make the existing Base Stronger", TRUE,"Low Conversion- Can be ignored") -> Moderate Conversion- Make the existing Base Stronger
A8: 7 | B8: Malkajgiri | C8: =VLOOKUP(B8,Telengana_Reaults_2019[[#All],[PC Name]:[BJP_STATUS]],13,FALSE) -> 0.19467034 | D8: =VLOOKUP(B8,Telengana_Reaults_2019[[#All],[PC Name]:[BJP_STATUS]], 18,FALSE) -> 0.49616118 | E8: =VLOOKUP(B8,Telengana_Results_2024[[#All],[PC Name]:[BJP vote share]],15,FALSE) -> 0.5160395 | F8: =VLOOKUP(B8,Telengana_Results_2024[[#All],[PC Name]:[BJP STATUS]],19,FALSE) -> 0.51275919 | G8: =E8-C8 -> 0.32136917 | H8: =F8-D8 -> 0.01659801 | I8: =G8/H8 -> 19.361909 | J8: =_xlfn.IFS(I8>5,"High Conversion- Mobilize Voters", I8>=3,"Moderate Conversion- Make the existing Base Stronger", TRUE,"Low Conversion- Can be ignored") -> High Conversion- Mobilize Voters
A9: 8 | B9: Secundrabad | C9: =VLOOKUP(B9,Telengana_Reaults_2019[[#All],[PC Name]:[BJP_STATUS]],13,FALSE) -> 0.42047588 | D9: =VLOOKUP(B9,Telengana_Reaults_2019[[#All],[PC Name]:[BJP_STATUS]], 18,FALSE) -> 0.46492768 | E9: =VLOOKUP(B9,Telengana_Results_2024[[#All],[PC Name]:[BJP vote share]],15,FALSE) -> 0.45373158 | F9: =VLOOKUP(B9,Telengana_Results_2024[[#All],[PC Name]:[BJP STATUS]],19,FALSE) -> 0.49449624 | G9: =E9-C9 -> 0.033255705 | H9: =F9-D9 -> 0.029568556 | I9: =G9/H9 -> 1.1246983 | J9: =_xlfn.IFS(I9>5,"High Conversion- Mobilize Voters", I9>=3,"Moderate Conversion- Make the existing Base Stronger", TRUE,"Low Conversion- Can be ignored") -> Low Conversion- Can be ignored
A10: 9 | B10: Hyderabad | C10: =VLOOKUP(B10,Telengana_Reaults_2019[[#All],[PC Name]:[BJP_STATUS]],13,FALSE) -> 0.26801743 | D10: =VLOOKUP(B10,Telengana_Reaults_2019[[#All],[PC Name]:[BJP_STATUS]], 18,FALSE) -> 0.44836718 | E10: =VLOOKUP(B10,Telengana_Results_2024[[#All],[PC Name]:[BJP vote share]],15,FALSE) -> 0.30062056 | F10: =VLOOKUP(B10,Telengana_Results_2024[[#All],[PC Name]:[BJP STATUS]],19,FALSE) -> 0.48792476 | G10: =E10-C10 -> 0.032603125 | H10: =F10-D10 -> 0.039557576 | I10: =G10/H10 -> 0.8241942 | J10: =_xlfn.IFS(I10>5,"High Conversion- Mobilize Voters", I10>=3,"Moderate Conversion- Make the existing Base Stronger", TRUE,"Low Conversion- Can be ignored") -> Low Conversion- Can be ignored
A11: 10 | B11: Chevella | C11: =VLOOKUP(B11,Telengana_Reaults_2019[[#All],[PC Name]:[BJP_STATUS]],13,FALSE) -> 0.15533067 | D11: =VLOOKUP(B11,Telengana_Reaults_2019[[#All],[PC Name]:[BJP_STATUS]], 18,FALSE) -> 0.53218764 | E11: =VLOOKUP(B11,Telengana_Results_2024[[#All],[PC Name]:[BJP vote share]],15,FALSE) -> 0.48526991 | F11: =VLOOKUP(B11,Telengana_Results_2024[[#All],[PC Name]:[BJP STATUS]],19,FALSE) -> 0.57029312 | G11: =E11-C11 -> 0.32993925 | H11: =F11-D11 -> 0.038105489 | I11: =G11/H11 -> 8.6585754 | J11: =_xlfn.IFS(I11>5,"High Conversion- Mobilize Voters", I11>=3,"Moderate Conversion- Make the existing Base Stronger", TRUE,"Low Conversion- Can be ignored") -> High Conversion- Mobilize Voters
A12: 11 | B12: Mahbubnagar | C12: =VLOOKUP(B12,Telengana_Reaults_2019[[#All],[PC Name]:[BJP_STATUS]],13,FALSE) -> 0.33877867 | D12: =VLOOKUP(B12,Telengana_Reaults_2019[[#All],[PC Name]:[BJP_STATUS]], 18,FALSE) -> 0.65376316 | E12: =VLOOKUP(B12,Telengana_Results_2024[[#All],[PC Name]:[BJP vote share]],15,FALSE) -> 0.41804611 | F12: =VLOOKUP(B12,Telengana_Results_2024[[#All],[PC Name]:[BJP STATUS]],19,FALSE) -> 0.72908086 | G12: =E12-C12 -> 0.079267438 | H12: =F12-D12 -> 0.075317698 | I12: =G12/H12 -> 1.0524411 | J12: =_xlfn.IFS(I12>5,"High Conversion- Mobilize Voters", I12>=3,"Moderate Conversion- Make the existing Base Stronger", TRUE,"Low Conversion- Can be ignored") -> Low Conversion- Can be ignored
A13: 12 | B13: Nagarkurnool | C13: =VLOOKUP(B13,Telengana_Reaults_2019[[#All],[PC Name]:[BJP_STATUS]],13,FALSE) -> 0.13034439 | D13: =VLOOKUP(B13,Telengana_Reaults_2019[[#All],[PC Name]:[BJP_STATUS]], 18,FALSE) -> 0.62328578 | E13: =VLOOKUP(B13,Telengana_Results_2024[[#All],[PC Name]:[BJP vote share]],15,FALSE) -> 0.30515798 | F13: =VLOOKUP(B13,Telengana_Results_2024[[#All],[PC Name]:[BJP STATUS]],19,FALSE) -> 0.70239693 | G13: =E13-C13 -> 0.17481359 | H13: =F13-D13 -> 0.07911115 | I13: =G13/H13 -> 2.2097213 | J13: =_xlfn.IFS(I13>5,"High Conversion- Mobilize Voters", I13>=3,"Moderate Conversion- Make the existing Base Stronger", TRUE,"Low Conversion- Can be ignored") -> Low Conversion- Can be ignored
... A18: 17 | B18: Khammam | C18: =VLOOKUP(B18,Telengana_Reaults_2019[[#All],[PC Name]:[BJP_STATUS]],13,FALSE) -> 0.017974594 | D18: =VLOOKUP(B18,Telengana_Reaults_2019[[#All],[PC Name]:[BJP_STATUS]], 18,FALSE) -> 0.75295562 | E18: =VLOOKUP(B18,Telengana_Results_2024[[#All],[PC Name]:[BJP vote share]],15,FALSE) -> 0.095328168 | F18: =VLOOKUP(B18,Telengana_Results_2024[[#All],[PC Name]:[BJP STATUS]],19,FALSE) -> 0.76735468 | G18: =E18-C18 -> 0.077353573 | H18: =F18-D18 -> 0.014399053 | I18: =G18/H18 -> 5.3721291 | J18: =_xlfn.IFS(I18>5,"High Conversion- Mobilize Voters", I18>=3,"Moderate Conversion- Make the existing Base Stronger", TRUE,"Low Conversion- Can be ignored") -> High Conversion- Mobilize Voters

Sheet SeatAnalysis&CandidateRating
A1: Sr.No | B1: PC Name | C1: Status 2019 | D1: Candidate 2019 | E1: BJP Votes Share 2019 | F1: BJP Status 2024 | G1: Candidate 2024 | H1: BJP Votes 2024 | I1: Bjp Presence | J1: Swing Seat Analysis
A2: 1 | B2: Adilabad | C2: =VLOOKUP(B2,Telengana_Reaults_2019[[#All],[PC Name]:[BJP_STATUS]],19,FALSE) -> BJP WON | D2: Soyam Bapu Rao | E2: =VLOOKUP('SeatAnalysis&CandidateRating'!B2,Telengana_Reaults_2019[[#All],[PC Name]:[BJP_STATUS]],13,FALSE) -> 0.35476484 | F2: =VLOOKUP(B2,Telengana_Results_2024[[#All],[PC Name]:[BJP STATUS]],20,FALSE) -> BJP WON | G2: Godam Nagesh | H2: =VLOOKUP('SeatAnalysis&CandidateRating'!B2,Telengana_Results_2024[[#All],[PC Name]:[BJP STATUS]],15,FALSE) -> 0.46425213 | I2: =_xlfn.IFS(AND(D2=G2,C2="BJP WON",F2="BJP WON"), "Strong Candidate Face", AND(D2<>G2,C2="BJP WON", F2="BJP WON"), "Strong Party Presence", AND(D2<>G2,H2>E2), "Pontential Candidate - Retain", TRUE, "Need Change") -> Strong Party Presence | J2: =_xlfn.IFS(AND(Table5[[#This Row],[Status 2019]]="BJP WON",Table5[[#This Row],[BJP Status 2024]]="BJP WON"), "Strong Seat", AND(Table5[[#This Row],[Status 2019]]<>"BJP WON", Table5[[#This Row],[BJP Status 2024]]<>"BJP WON" ),"Weak Seat", TRUE, "Swing Seat") -> Strong Seat
A3: 2 | B3: Peddapalle | C3: =VLOOKUP(B3,Telengana_Reaults_2019[[#All],[PC Name]:[BJP_STATUS]],19,FALSE) -> BJP LOST | D3: S.Kumar | E3: =VLOOKUP('SeatAnalysis&CandidateRating'!B3,Telengana_Reaults_2019[[#All],[PC Name]:[BJP_STATUS]],13,FALSE) -> 0.095465084 | F3: =VLOOKUP(B3,Telengana_Results_2024[[#All],[PC Name]:[BJP STATUS]],20,FALSE) -> BJP LOST | G3: Srinivas Gomase | H3: =VLOOKUP('SeatAnalysis&CandidateRating'!B3,Telengana_Results_2024[[#All],[PC Name]:[BJP STATUS]],15,FALSE) -> 0.31592149 | I3: =_xlfn.IFS(AND(D3=G3,C3="BJP WON",F3="BJP WON"), "Strong Candidate Face", AND(D3<>G3,C3="BJP WON", F3="BJP WON"), "Strong Party Presence", AND(D3<>G3,H3>E3), "Pontential Candidate - Retain", TRUE, "Need Change") -> Pontential Candidate - Retain | J3: =_xlfn.IFS(AND(Table5[[#This Row],[Status 2019]]="BJP WON",Table5[[#This Row],[BJP Status 2024]]="BJP WON"), "Strong Seat", AND(Table5[[#This Row],[Status 2019]]<>"BJP WON", Table5[[#This Row],[BJP Status 2024]]<>"BJP WON" ),"Weak Seat", TRUE, "Swing Seat") -> Weak Seat
A4: 3 | B4: Karimnagar | C4: =VLOOKUP(B4,Telengana_Reaults_2019[[#All],[PC Name]:[BJP_STATUS]],19,FALSE) -> BJP WON | D4: Bandi Sanjay Kumar | E4: =VLOOKUP('SeatAnalysis&CandidateRating'!B4,Telengana_Reaults_2019[[#All],[PC Name]:[BJP_STATUS]],13,FALSE) -> 0.43415292 | F4: =VLOOKUP(B4,Telengana_Results_2024[[#All],[PC Name]:[BJP STATUS]],20,FALSE) -> BJP WON | G4: Bandi Sanjay Kumar | H4: =VLOOKUP('SeatAnalysis&CandidateRating'!B4,Telengana_Results_2024[[#All],[PC Name]:[BJP STATUS]],15,FALSE) -> 0.44753689 | I4: =_xlfn.IFS(AND(D4=G4,C4="BJP WON",F4="BJP WON"), "Strong Candidate Face", AND(D4<>G4,C4="BJP WON", F4="BJP WON"), "Strong Party Presence", AND(D4<>G4,H4>E4), "Pontential Candidate - Retain", TRUE, "Need Change") -> Strong Candidate Face | J4: =_xlfn.IFS(AND(Table5[[#This Row],[Status 2019]]="BJP WON",Table5[[#This Row],[BJP Status 2024]]="BJP WON"), "Strong Seat", AND(Table5[[#This Row],[Status 2019]]<>"BJP WON", Table5[[#This Row],[BJP Status 2024]]<>"BJP WON" ),"Weak Seat", TRUE, "Swing Seat") -> Strong Seat
A5: 4 | B5: Nizamabad | C5: =VLOOKUP(B5,Telengana_Reaults_2019[[#All],[PC Name]:[BJP_STATUS]],19,FALSE) -> BJP WON | D5: Arvind Dharmapuri | E5: =VLOOKUP('SeatAnalysis&CandidateRating'!B5,Telengana_Reaults_2019[[#All],[PC Name]:[BJP_STATUS]],13,FALSE) -> 0.45220029 | F5: =VLOOKUP(B5,Telengana_Results_2024[[#All],[PC Name]:[BJP STATUS]],20,FALSE) -> BJP WON | G5: Arvind Dharmapuri | H5: =VLOOKUP('SeatAnalysis&CandidateRating'!B5,Telengana_Results_2024[[#All],[PC Name]:[BJP STATUS]],15,FALSE) -> 0.48191275 | I5: =_xlfn.IFS(AND(D5=G5,C5="BJP WON",F5="BJP WON"), "Strong Candidate Face", AND(D5<>G5,C5="BJP WON", F5="BJP WON"), "Strong Party Presence", AND(D5<>G5,H5>E5), "Pontential Candidate - Retain", TRUE, "Need Change") -> Strong Candidate Face | J5: =_xlfn.IFS(AND(Table5[[#This Row],[Status 2019]]="BJP WON",Table5[[#This Row],[BJP Status 2024]]="BJP WON"), "Strong Seat", AND(Table5[[#This Row],[Status 2019]]<>"BJP WON", Table5[[#This Row],[BJP Status 2024]]<>"BJP WON" ),"Weak Seat", TRUE, "Swing Seat") -> Strong Seat
A6: 5 | B6: Zahirabad | C6: =VLOOKUP(B6,Telengana_Reaults_2019[[#All],[PC Name]:[BJP_STATUS]],19,FALSE) -> BJP LOST | D6: Banala Laxma Reddy | E6: =VLOOKUP('SeatAnalysis&CandidateRating'!B6,Telengana_Reaults_2019[[#All],[PC Name]:[BJP_STATUS]],13,FALSE) -> 0.13304448 | F6: =VLOOKUP(B6,Telengana_Results_2024[[#All],[PC Name]:[BJP STATUS]],20,FALSE) -> BJP LOST | G6: B. B. Patil | H6: =VLOOKUP('SeatAnalysis&CandidateRating'!B6,Telengana_Results_2024[[#All],[PC Name]:[BJP STATUS]],15,FALSE) -> 0.39090771 | I6: =_xlfn.IFS(AND(D6=G6,C6="BJP WON",F6="BJP WON"), "Strong Candidate Face", AND(D6<>G6,C6="BJP WON", F6="BJP WON"), "Strong Party Presence", AND(D6<>G6,H6>E6), "Pontential Candidate - Retain", TRUE, "Need Change") -> Pontential Candidate - Retain | J6: =_xlfn.IFS(AND(Table5[[#This Row],[Status 2019]]="BJP WON",Table5[[#This Row],[BJP Status 2024]]="BJP WON"), "Strong Seat", AND(Table5[[#This Row],[Status 2019]]<>"BJP WON", Table5[[#This Row],[BJP Status 2024]]<>"BJP WON" ),"Weak Seat", TRUE, "Swing Seat") -> Weak Seat
A7: 6 | B7: Medak | C7: =VLOOKUP(B7,Telengana_Reaults_2019[[#All],[PC Name]:[BJP_STATUS]],19,FALSE) -> BJP LOST | D7: Madavaneni Raghunandan Rao | E7: =VLOOKUP('SeatAnalysis&CandidateRating'!B7,Telengana_Reaults_2019[[#All],[PC Name]:[BJP_STATUS]],13,FALSE) -> 0.17524167 | F7: =VLOOKUP(B7,Telengana_Results_2024[[#All],[PC Name]:[BJP STATUS]],20,FALSE) -> BJP WON | G7: Madhavaneni Raghunandan Rao | H7: =VLOOKUP('SeatAnalysis&CandidateRating'!B7,Telengana_Results_2024[[#All],[PC Name]:[BJP STATUS]],15,FALSE) -> 0.34106072 | I7: =_xlfn.IFS(AND(D7=G7,C7="BJP WON",F7="BJP WON"), "Strong Candidate Face", AND(D7<>G7,C7="BJP WON", F7="BJP WON"), "Strong Party Presence", AND(D7<>G7,H7>E7), "Pontential Candidate - Retain", TRUE, "Need Change") -> Pontential Candidate - Retain | J7: =_xlfn.IFS(AND(Table5[[#This Row],[Status 2019]]="BJP WON",Table5[[#This Row],[BJP Status 2024]]="BJP WON"), "Strong Seat", AND(Table5[[#This Row],[Status 2019]]<>"BJP WON", Table5[[#This Row],[BJP Status 2024]]<>"BJP WON" ),"Weak Seat", TRUE, "Swing Seat") -> Swing Seat
A8: 7 | B8: Malkajgiri | C8: =VLOOKUP(B8,Telengana_Reaults_2019[[#All],[PC Name]:[BJP_STATUS]],19,FALSE) -> BJP LOST | D8: Ramchander Rao Naraparaju | E8: =VLOOKUP('SeatAnalysis&CandidateRating'!B8,Telengana_Reaults_2019[[#All],[PC Name]:[BJP_STATUS]],13,FALSE) -> 0.19467034 | F8: =VLOOKUP(B8,Telengana_Results_2024[[#All],[PC Name]:[BJP STATUS]],20,FALSE) -> BJP WON | G8: Eatala Rajender | H8: =VLOOKUP('SeatAnalysis&CandidateRating'!B8,Telengana_Results_2024[[#All],[PC Name]:[BJP STATUS]],15,FALSE) -> 0.5160395 | I8: =_xlfn.IFS(AND(D8=G8,C8="BJP WON",F8="BJP WON"), "Strong Candidate Face", AND(D8<>G8,C8="BJP WON", F8="BJP WON"), "Strong Party Presence", AND(D8<>G8,H8>E8), "Pontential Candidate - Retain", TRUE, "Need Change") -> Pontential Candidate - Retain | J8: =_xlfn.IFS(AND(Table5[[#This Row],[Status 2019]]="BJP WON",Table5[[#This Row],[BJP Status 2024]]="BJP WON"), "Strong Seat", AND(Table5[[#This Row],[Status 2019]]<>"BJP WON", Table5[[#This Row],[BJP Status 2024]]<>"BJP WON" ),"Weak Seat", TRUE, "Swing Seat") -> Swing Seat
A9: 8 | B9: Secundrabad | C9: =VLOOKUP(B9,Telengana_Reaults_2019[[#All],[PC Name]:[BJP_STATUS]],19,FALSE) -> BJP WON | D9: G. Kishan Reddy | E9: =VLOOKUP('SeatAnalysis&CandidateRating'!B9,Telengana_Reaults_2019[[#All],[PC Name]:[BJP_STATUS]],13,FALSE) -> 0.42047588 | F9: =VLOOKUP(B9,Telengana_Results_2024[[#All],[PC Name]:[BJP STATUS]],20,FALSE) -> BJP WON | G9: G. Kishan Reddy | H9: =VLOOKUP('SeatAnalysis&CandidateRating'!B9,Telengana_Results_2024[[#All],[PC Name]:[BJP STATUS]],15,FALSE) -> 0.45373158 | I9: =_xlfn.IFS(AND(D9=G9,C9="BJP WON",F9="BJP WON"), "Strong Candidate Face", AND(D9<>G9,C9="BJP WON", F9="BJP WON"), "Strong Party Presence", AND(D9<>G9,H9>E9), "Pontential Candidate - Retain", TRUE, "Need Change") -> Strong Candidate Face | J9: =_xlfn.IFS(AND(Table5[[#This Row],[Status 2019]]="BJP WON",Table5[[#This Row],[BJP Status 2024]]="BJP WON"), "Strong Seat", AND(Table5[[#This Row],[Status 2019]]<>"BJP WON", Table5[[#This Row],[BJP Status 2024]]<>"BJP WON" ),"Weak Seat", TRUE, "Swing Seat") -> Strong Seat
A10: 9 | B10: Hyderabad | C10: =VLOOKUP(B10,Telengana_Reaults_2019[[#All],[PC Name]:[BJP_STATUS]],19,FALSE) -> BJP LOST | D10: Dr. Bhagavanth Rao | E10: =VLOOKUP('SeatAnalysis&CandidateRating'!B10,Telengana_Reaults_2019[[#All],[PC Name]:[BJP_STATUS]],13,FALSE) -> 0.26801743 | F10: =VLOOKUP(B10,Telengana_Results_2024[[#All],[PC Name]:[BJP STATUS]],20,FALSE) -> BJP LOST | G10: Madhavi Latha Kompella | H10: =VLOOKUP('SeatAnalysis&CandidateRating'!B10,Telengana_Results_2024[[#All],[PC Name]:[BJP STATUS]],15,FALSE) -> 0.30062056 | I10: =_xlfn.IFS(AND(D10=G10,C10="BJP WON",F10="BJP WON"), "Strong Candidate Face", AND(D10<>G10,C10="BJP WON", F10="BJP WON"), "Strong Party Presence", AND(D10<>G10,H10>E10), "Pontential Candidate - Retain", TRUE, "Need Change") -> Pontential Candidate - Retain | J10: =_xlfn.IFS(AND(Table5[[#This Row],[Status 2019]]="BJP WON",Table5[[#This Row],[BJP Status 2024]]="BJP WON"), "Strong Seat", AND(Table5[[#This Row],[Status 2019]]<>"BJP WON", Table5[[#This Row],[BJP Status 2024]]<>"BJP WON" ),"Weak Seat", TRUE, "Swing Seat") -> Weak Seat
A11: 10 | B11: Chevella | C11: =VLOOKUP(B11,Telengana_Reaults_2019[[#All],[PC Name]:[BJP_STATUS]],19,FALSE) -> BJP LOST | D11: B. Janardhan Reddy | E11: =VLOOKUP('SeatAnalysis&CandidateRating'!B11,Telengana_Reaults_2019[[#All],[PC Name]:[BJP_STATUS]],13,FALSE) -> 0.15533067 | F11: =VLOOKUP(B11,Telengana_Results_2024[[#All],[PC Name]:[BJP STATUS]],20,FALSE) -> BJP WON | G11: Konda Vishweshwar Reddy | H11: =VLOOKUP('SeatAnalysis&CandidateRating'!B11,Telengana_Results_2024[[#All],[PC Name]:[BJP STATUS]],15,FALSE) -> 0.48526991 | I11: =_xlfn.IFS(AND(D11=G11,C11="BJP WON",F11="BJP WON"), "Strong Candidate Face", AND(D11<>G11,C11="BJP WON", F11="BJP WON"), "Strong Party Presence", AND(D11<>G11,H11>E11), "Pontential Candidate - Retain", TRUE, "Need Change") -> Pontential Candidate - Retain | J11: =_xlfn.IFS(AND(Table5[[#This Row],[Status 2019]]="BJP WON",Table5[[#This Row],[BJP Status 2024]]="BJP WON"), "Strong Seat", AND(Table5[[#This Row],[Status 2019]]<>"BJP WON", Table5[[#This Row],[BJP Status 2024]]<>"BJP WON" ),"Weak Seat", TRUE, "Swing Seat") -> Swing Seat
A12: 11 | B12: Mahbubnagar | C12: =VLOOKUP(B12,Telengana_Reaults_2019[[#All],[PC Name]:[BJP_STATUS]],19,FALSE) -> BJP LOST | D12: Aruna D.K | E12: =VLOOKUP('SeatAnalysis&CandidateRating'!B12,Telengana_Reaults_2019[[#All],[PC Name]:[BJP_STATUS]],13,FALSE) -> 0.33877867 | F12: =VLOOKUP(B12,Telengana_Results_2024[[#All],[PC Name]:[BJP STATUS]],20,FALSE) -> BJP WON | G12: Aruna. D. K | H12: =VLOOKUP('SeatAnalysis&CandidateRating'!B12,Telengana_Results_2024[[#All],[PC Name]:[BJP STATUS]],15,FALSE) -> 0.41804611 | I12: =_xlfn.IFS(AND(D12=G12,C12="BJP WON",F12="BJP WON"), "Strong Candidate Face", AND(D12<>G12,C12="BJP WON", F12="BJP WON"), "Strong Party Presence", AND(D12<>G12,H12>E12), "Pontential Candidate - Retain", TRUE, "Need Change") -> Pontential Candidate - Retain | J12: =_xlfn.IFS(AND(Table5[[#This Row],[Status 2019]]="BJP WON",Table5[[#This Row],[BJP Status 2024]]="BJP WON"), "Strong Seat", AND(Table5[[#This Row],[Status 2019]]<>"BJP WON", Table5[[#This Row],[BJP Status 2024]]<>"BJP WON" ),"Weak Seat", TRUE, "Swing Seat") -> Swing Seat
A13: 12 | B13: Nagarkurnool | C13: =VLOOKUP(B13,Telengana_Reaults_2019[[#All],[PC Name]:[BJP_STATUS]],19,FALSE) -> BJP LOST | D13: Shruthi Bangaru Alias Bangaru Shruthi | E13: =VLOOKUP('SeatAnalysis&CandidateRating'!B13,Telengana_Reaults_2019[[#All],[PC Name]:[BJP_STATUS]],13,FALSE) -> 0.13034439 | F13: =VLOOKUP(B13,Telengana_Results_2024[[#All],[PC Name]:[BJP STATUS]],20,FALSE) -> BJP LOST | G13: Bharath Prasad Pothuganti | H13: =VLOOKUP('SeatAnalysis&CandidateRating'!B13,Telengana_Results_2024[[#All],[PC Name]:[BJP STATUS]],15,FALSE) -> 0.30515798 | I13: =_xlfn.IFS(AND(D13=G13,C13="BJP WON",F13="BJP WON"), "Strong Candidate Face", AND(D13<>G13,C13="BJP WON", F13="BJP WON"), "Strong Party Presence", AND(D13<>G13,H13>E13), "Pontential Candidate - Retain", TRUE, "Need Change") -> Pontential Candidate - Retain | J13: =_xlfn.IFS(AND(Table5[[#This Row],[Status 2019]]="BJP WON",Table5[[#This Row],[BJP Status 2024]]="BJP WON"), "Strong Seat", AND(Table5[[#This Row],[Status 2019]]<>"BJP WON", Table5[[#This Row],[BJP Status 2024]]<>"BJP WON" ),"Weak Seat", TRUE, "Swing Seat") -> Weak Seat
... A18: 17 | B18: Khammam | C18: =VLOOKUP(B18,Telengana_Reaults_2019[[#All],[PC Name]:[BJP_STATUS]],19,FALSE) -> BJP LOST | D18: Devaki Vasudeva Rao | E18: =VLOOKUP('SeatAnalysis&CandidateRating'!B18,Telengana_Reaults_2019[[#All],[PC Name]:[BJP_STATUS]],13,FALSE) -> 0.017974594 | F18: =VLOOKUP(B18,Telengana_Results_2024[[#All],[PC Name]:[BJP STATUS]],20,FALSE) -> BJP LOST | G18: Vinod Rao Tandra | H18: =VLOOKUP('SeatAnalysis&CandidateRating'!B18,Telengana_Results_2024[[#All],[PC Name]:[BJP STATUS]],15,FALSE) -> 0.095328168 | I18: =_xlfn.IFS(AND(D18=G18,C18="BJP WON",F18="BJP WON"), "Strong Candidate Face", AND(D18<>G18,C18="BJP WON", F18="BJP WON"), "Strong Party Presence", AND(D18<>G18,H18>E18), "Pontential Candidate - Retain", TRUE, "Need Change") -> Pontential Candidate - Retain | J18: =_xlfn.IFS(AND(Table5[[#This Row],[Status 2019]]="BJP WON",Table5[[#This Row],[BJP Status 2024]]="BJP WON"), "Strong Seat", AND(Table5[[#This Row],[Status 2019]]<>"BJP WON", Table5[[#This Row],[BJP Status 2024]]<>"BJP WON" ),"Weak Seat", TRUE, "Swing Seat") -> Weak Seat

Sheet Decision
A1: Sr.No | B1: PC Name | C1: Bjp_Hold | D1: Candidate Rating | E1: Seat Type | F1: Turn Out Factor | G1: Decision
A2: 1 | B2: Adilabad | C2: =VLOOKUP(Decision!B2,Table3[[PC Name]:[Seat Grade ]],8,FALSE) -> Average Hold | D2: =VLOOKUP(B2,Table5[],8,FALSE) -> Strong Party Presence | E2: =VLOOKUP(B2,Table5[],9,FALSE) -> Strong Seat | F2: =VLOOKUP(B2,Table4[[PC Name]:[Conversion Rate]],9,FALSE) -> Moderate Conversion- Make the existing Base Stronger | G2: =_xlfn.IFS( OR(D2="Strong Candidate Face", D2="Strong Party Presence"), "Invest & Maintain", AND(E2="Strong Seat", OR(C2="Strong Hold", C2="Good Hold")), "Protect & Maintain", OR( AND(E2="Swing Seat", OR(F2="High Conversion- Mobilize Voters", F2="Moderate Conversion- Make the existing Base Stronger")), AND(E2="Strong Seat", C2="Average Hold") ), "Invest to Flip", AND(E2="Weak Seat", F2="High Conversion- Mobilize Voters"), "Mobilize Aggressively", TRUE, "Deprioritize" ) -> Invest & Maintain
A3: 2 | B3: Peddapalle | C3: =VLOOKUP(Decision!B3,Table3[[PC Name]:[Seat Grade ]],8,FALSE) -> Very Vulnerable Hold | D3: =VLOOKUP(B3,Table5[],8,FALSE) -> Pontential Candidate - Retain | E3: =VLOOKUP(B3,Table5[],9,FALSE) -> Weak Seat | F3: =VLOOKUP(B3,Table4[[PC Name]:[Conversion Rate]],9,FALSE) -> High Conversion- Mobilize Voters | G3: =_xlfn.IFS( OR(D3="Strong Candidate Face", D3="Strong Party Presence"), "Invest & Maintain", AND(E3="Strong Seat", OR(C3="Strong Hold", C3="Good Hold")), "Protect & Maintain", OR( AND(E3="Swing Seat", OR(F3="High Conversion- Mobilize Voters", F3="Moderate Conversion- Make the existing Base Stronger")), AND(E3="Strong Seat", C3="Average Hold") ), "Invest to Flip", AND(E3="Weak Seat", F3="High Conversion- Mobilize Voters"), "Mobilize Aggressively", TRUE, "Deprioritize" ) -> Mobilize Aggressively
A4: 3 | B4: Karimnagar | C4: =VLOOKUP(Decision!B4,Table3[[PC Name]:[Seat Grade ]],8,FALSE) -> Strong Hold | D4: =VLOOKUP(B4,Table5[],8,FALSE) -> Strong Candidate Face | E4: =VLOOKUP(B4,Table5[],9,FALSE) -> Strong Seat | F4: =VLOOKUP(B4,Table4[[PC Name]:[Conversion Rate]],9,FALSE) -> Low Conversion- Can be ignored | G4: =_xlfn.IFS( OR(D4="Strong Candidate Face", D4="Strong Party Presence"), "Invest & Maintain", AND(E4="Strong Seat", OR(C4="Strong Hold", C4="Good Hold")), "Protect & Maintain", OR( AND(E4="Swing Seat", OR(F4="High Conversion- Mobilize Voters", F4="Moderate Conversion- Make the existing Base Stronger")), AND(E4="Strong Seat", C4="Average Hold") ), "Invest to Flip", AND(E4="Weak Seat", F4="High Conversion- Mobilize Voters"), "Mobilize Aggressively", TRUE, "Deprioritize" ) -> Invest & Maintain
A5: 4 | B5: Nizamabad | C5: =VLOOKUP(Decision!B5,Table3[[PC Name]:[Seat Grade ]],8,FALSE) -> Average Hold | D5: =VLOOKUP(B5,Table5[],8,FALSE) -> Strong Candidate Face | E5: =VLOOKUP(B5,Table5[],9,FALSE) -> Strong Seat | F5: =VLOOKUP(B5,Table4[[PC Name]:[Conversion Rate]],9,FALSE) -> Low Conversion- Can be ignored | G5: =_xlfn.IFS( OR(D5="Strong Candidate Face", D5="Strong Party Presence"), "Invest & Maintain", AND(E5="Strong Seat", OR(C5="Strong Hold", C5="Good Hold")), "Protect & Maintain", OR( AND(E5="Swing Seat", OR(F5="High Conversion- Mobilize Voters", F5="Moderate Conversion- Make the existing Base Stronger")), AND(E5="Strong Seat", C5="Average Hold") ), "Invest to Flip", AND(E5="Weak Seat", F5="High Conversion- Mobilize Voters"), "Mobilize Aggressively", TRUE, "Deprioritize" ) -> Invest & Maintain
A6: 5 | B6: Zahirabad | C6: =VLOOKUP(Decision!B6,Table3[[PC Name]:[Seat Grade ]],8,FALSE) -> Very Vulnerable Hold | D6: =VLOOKUP(B6,Table5[],8,FALSE) -> Pontential Candidate - Retain | E6: =VLOOKUP(B6,Table5[],9,FALSE) -> Weak Seat | F6: =VLOOKUP(B6,Table4[[PC Name]:[Conversion Rate]],9,FALSE) -> Moderate Conversion- Make the existing Base Stronger | G6: =_xlfn.IFS( OR(D6="Strong Candidate Face", D6="Strong Party Presence"), "Invest & Maintain", AND(E6="Strong Seat", OR(C6="Strong Hold", C6="Good Hold")), "Protect & Maintain", OR( AND(E6="Swing Seat", OR(F6="High Conversion- Mobilize Voters", F6="Moderate Conversion- Make the existing Base Stronger")), AND(E6="Strong Seat", C6="Average Hold") ), "Invest to Flip", AND(E6="Weak Seat", F6="High Conversion- Mobilize Voters"), "Mobilize Aggressively", TRUE, "Deprioritize" ) -> Deprioritize
A7: 6 | B7: Medak | C7: =VLOOKUP(Decision!B7,Table3[[PC Name]:[Seat Grade ]],8,FALSE) -> Very Vulnerable Hold | D7: =VLOOKUP(B7,Table5[],8,FALSE) -> Pontential Candidate - Retain | E7: =VLOOKUP(B7,Table5[],9,FALSE) -> Swing Seat | F7: =VLOOKUP(B7,Table4[[PC Name]:[Conversion Rate]],9,FALSE) -> Moderate Conversion- Make the existing Base Stronger | G7: =_xlfn.IFS( OR(D7="Strong Candidate Face", D7="Strong Party Presence"), "Invest & Maintain", AND(E7="Strong Seat", OR(C7="Strong Hold", C7="Good Hold")), "Protect & Maintain", OR( AND(E7="Swing Seat", OR(F7="High Conversion- Mobilize Voters", F7="Moderate Conversion- Make the existing Base Stronger")), AND(E7="Strong Seat", C7="Average Hold") ), "Invest to Flip", AND(E7="Weak Seat", F7="High Conversion- Mobilize Voters"), "Mobilize Aggressively", TRUE, "Deprioritize" ) -> Invest to Flip
A8: 7 | B8: Malkajgiri | C8: =VLOOKUP(Decision!B8,Table3[[PC Name]:[Seat Grade ]],8,FALSE) -> Weak Hold | D8: =VLOOKUP(B8,Table5[],8,FALSE) -> Pontential Candidate - Retain | E8: =VLOOKUP(B8,Table5[],9,FALSE) -> Swing Seat | F8: =VLOOKUP(B8,Table4[[PC Name]:[Conversion Rate]],9,FALSE) -> High Conversion- Mobilize Voters | G8: =_xlfn.IFS( OR(D8="Strong Candidate Face", D8="Strong Party Presence"), "Invest & Maintain", AND(E8="Strong Seat", OR(C8="Strong Hold", C8="Good Hold")), "Protect & Maintain", OR( AND(E8="Swing Seat", OR(F8="High Conversion- Mobilize Voters", F8="Moderate Conversion- Make the existing Base Stronger")), AND(E8="Strong Seat", C8="Average Hold") ), "Invest to Flip", AND(E8="Weak Seat", F8="High Conversion- Mobilize Voters"), "Mobilize Aggressively", TRUE, "Deprioritize" ) -> Invest to Flip
A9: 8 | B9: Secundrabad | C9: =VLOOKUP(Decision!B9,Table3[[PC Name]:[Seat Grade ]],8,FALSE) -> Average Hold | D9: =VLOOKUP(B9,Table5[],8,FALSE) -> Strong Candidate Face | E9: =VLOOKUP(B9,Table5[],9,FALSE) -> Strong Seat | F9: =VLOOKUP(B9,Table4[[PC Name]:[Conversion Rate]],9,FALSE) -> Low Conversion- Can be ignored | G9: =_xlfn.IFS( OR(D9="Strong Candidate Face", D9="Strong Party Presence"), "Invest & Maintain", AND(E9="Strong Seat", OR(C9="Strong Hold", C9="Good Hold")), "Protect & Maintain", OR( AND(E9="Swing Seat", OR(F9="High Conversion- Mobilize Voters", F9="Moderate Conversion- Make the existing Base Stronger")), AND(E9="Strong Seat", C9="Average Hold") ), "Invest to Flip", AND(E9="Weak Seat", F9="High Conversion- Mobilize Voters"), "Mobilize Aggressively", TRUE, "Deprioritize" ) -> Invest & Maintain
A10: 9 | B10: Hyderabad | C10: =VLOOKUP(Decision!B10,Table3[[PC Name]:[Seat Grade ]],8,FALSE) -> Very Vulnerable Hold | D10: =VLOOKUP(B10,Table5[],8,FALSE) -> Pontential Candidate - Retain | E10: =VLOOKUP(B10,Table5[],9,FALSE) -> Weak Seat | F10: =VLOOKUP(B10,Table4[[PC Name]:[Conversion Rate]],9,FALSE) -> Low Conversion- Can be ignored | G10: =_xlfn.IFS( OR(D10="Strong Candidate Face", D10="Strong Party Presence"), "Invest & Maintain", AND(E10="Strong Seat", OR(C10="Strong Hold", C10="Good Hold")), "Protect & Maintain", OR( AND(E10="Swing Seat", OR(F10="High Conversion- Mobilize Voters", F10="Moderate Conversion- Make the existing Base Stronger")), AND(E10="Strong Seat", C10="Average Hold") ), "Invest to Flip", AND(E10="Weak Seat", F10="High Conversion- Mobilize Voters"), "Mobilize Aggressively", TRUE, "Deprioritize" ) -> Deprioritize
A11: 10 | B11: Chevella | C11: =VLOOKUP(Decision!B11,Table3[[PC Name]:[Seat Grade ]],8,FALSE) -> Very Vulnerable Hold | D11: =VLOOKUP(B11,Table5[],8,FALSE) -> Pontential Candidate - Retain | E11: =VLOOKUP(B11,Table5[],9,FALSE) -> Swing Seat | F11: =VLOOKUP(B11,Table4[[PC Name]:[Conversion Rate]],9,FALSE) -> High Conversion- Mobilize Voters | G11: =_xlfn.IFS( OR(D11="Strong Candidate Face", D11="Strong Party Presence"), "Invest & Maintain", AND(E11="Strong Seat", OR(C11="Strong Hold", C11="Good Hold")), "Protect & Maintain", OR( AND(E11="Swing Seat", OR(F11="High Conversion- Mobilize Voters", F11="Moderate Conversion- Make the existing Base Stronger")), AND(E11="Strong Seat", C11="Average Hold") ), "Invest to Flip", AND(E11="Weak Seat", F11="High Conversion- Mobilize Voters"), "Mobilize Aggressively", TRUE, "Deprioritize" ) -> Invest to Flip
A12: 11 | B12: Mahbubnagar | C12: =VLOOKUP(Decision!B12,Table3[[PC Name]:[Seat Grade ]],8,FALSE) -> Weak Hold | D12: =VLOOKUP(B12,Table5[],8,FALSE) -> Pontential Candidate - Retain | E12: =VLOOKUP(B12,Table5[],9,FALSE) -> Swing Seat | F12: =VLOOKUP(B12,Table4[[PC Name]:[Conversion Rate]],9,FALSE) -> Low Conversion- Can be ignored | G12: =_xlfn.IFS( OR(D12="Strong Candidate Face", D12="Strong Party Presence"), "Invest & Maintain", AND(E12="Strong Seat", OR(C12="Strong Hold", C12="Good Hold")), "Protect & Maintain", OR( AND(E12="Swing Seat", OR(F12="High Conversion- Mobilize Voters", F12="Moderate Conversion- Make the existing Base Stronger")), AND(E12="Strong Seat", C12="Average Hold") ), "Invest to Flip", AND(E12="Weak Seat", F12="High Conversion- Mobilize Voters"), "Mobilize Aggressively", TRUE, "Deprioritize" ) -> Deprioritize
A13: 12 | B13: Nagarkurnool | C13: =VLOOKUP(Decision!B13,Table3[[PC Name]:[Seat Grade ]],8,FALSE) -> Very Vulnerable Hold | D13: =VLOOKUP(B13,Table5[],8,FALSE) -> Pontential Candidate - Retain | E13: =VLOOKUP(B13,Table5[],9,FALSE) -> Weak Seat | F13: =VLOOKUP(B13,Table4[[PC Name]:[Conversion Rate]],9,FALSE) -> Low Conversion- Can be ignored | G13: =_xlfn.IFS( OR(D13="Strong Candidate Face", D13="Strong Party Presence"), "Invest & Maintain", AND(E13="Strong Seat", OR(C13="Strong Hold", C13="Good Hold")), "Protect & Maintain", OR( AND(E13="Swing Seat", OR(F13="High Conversion- Mobilize Voters", F13="Moderate Conversion- Make the existing Base Stronger")), AND(E13="Strong Seat", C13="Average Hold") ), "Invest to Flip", AND(E13="Weak Seat", F13="High Conversion- Mobilize Voters"), "Mobilize Aggressively", TRUE, "Deprioritize" ) -> Deprioritize
